Workbook
Name Insumos: '1) Planilla maestra insumos'!$B$2:$F$99
Name Packaging: '4) Packaging'!$B$3:$G$1048576
Name Prodfinales: '3) costo mp'!#REF!
Name Recetas: '2) Recetas'!$B$2:$J$159
Name SegmentaciónDeDatos_Clasificacion: #N/A

Sheet 1) Planilla maestra insumos
B2: Insumo | C2: Unidad base | D2: Cantidad proveniente del proveedor | E2: Costo proveedor | F2: Precio unitario | G2: Ultima fecha
B3: Almidon de maiz | C3: kg | D3: 5 | E3: 8000 | F3: =+E3/D3 -> 1600
B4: Azucar blanca | C4: kg | D4: 10 | E4: 12635 | F4: =+E4/D4 -> 1263.5 | G4: 46219
B5: Azucar glass | C5: kg | D5: 10 | E5: 17500 | F5: =+E5/D5 -> 1750 | G5: 46111
B6: Azucar mascabo | C6: kg | D6: 10 | E6: 30938 | F6: =+E6/D6 -> 3093.8 | G6: ?
B7: Barra de kinder | C7: tabla | D7: 8 | E7: 4171 | F7: =+E7/D7 -> 521.375 | G7: ?
B8: Bicarbonato | C8: kg | D8: 1 | E8: 6000 | F8: =+E8/D8 -> 6000 | G8: 46220
B9: Bombon ferrero rocher | C9: unidades | D9: 8 | E9: 9000 | F9: =+E9/D9 -> 1125 | G9: 46226
B10: Bon o bon | C10: caja | D10: 30 | E10: 13317 | F10: =+E10/D10 -> 443.9 | G10: 46199
B11: Brownie clasico | C11: unidades | D11: 1 | E11: 720 | F11: =+E11/D11 -> 720
B12: Cacao alcalino | C12: kg | D12: 1 | E12: 23680 | F12: =+E12/D12 -> 23680 | G12: 46207
B13: Cacao amargo | C13: kg | D13: 25 | E13: 599250 | F13: =+E13/D13 -> 23970 | G13: 46219
B14: Caja chica | C14: unidades | D14: 2000 | E14: 216000 | F14: =+E14/D14 -> 108 | G14: ?
B15: Caja grande | C15: unidades | D15: 2000 | E15: 349370 | F15: =+E15/D15 -> 174.685 | G15: ?
B16: Caja para huevos | C16: unidades | D16: 1 | E16: 1135 | F16: =+E16/D16 -> 1135 | G16: -
B17: Chocolate blanco chip | C17: kg | D17: 6 | E17: 63147 | F17: =+E17/D17 -> 10524.5 | G17: ?
B18: Chocolate semiamargo chip | C18: kg | D18: 6 | E18: 63147 | F18: =+E18/D18 -> 10524.5 | G18: ?
B19: Chocolina | C19: gr | D19: 250 | E19: 1992 | F19: =+E19/D19 -> 7.968 | G19: 46199
B20: Colorante | C20: gr | D20: 15 | E20: 1100 | F20: =+E20/D20 -> 73.333333 | G20: ?
B21: Cookie chip adorno | C21: unidades | D21: 1 | E21: 300 | F21: =+E21/D21 -> 300
B22: Crema de leche | C22: kg | D22: 4 | E22: 38426 | F22: =+E22/D22 -> 9606.5 | G22: 46219
B23: Cucharas | C23: unidades | D23: 1 | E23: 136 | F23: =+E23/D23 -> 136
B24: Extracto de vainilla | C24: Lt | D24: 5 | E24: 134209 | F24: =+E24/D24 -> 26841.8 | G24: 46227
B25: Franui | C25: gr | D25: 150 | E25: 7064 | F25: =+E25/D25 -> 47.093333 | G25: 46191
B26: Frutos rojos | C26: kg | D26: 1 | E26: 9679 | F26: =+E26/D26 -> 9679 | G26: 46192
B27: Harina 000 | C27: kg | D27: 25 | E27: 17300 | F27: =+E27/D27 -> 692 | G27: ?
B28: Harina 0000 | C28: kg | D28: 25 | E28: 19700 | F28: =+E28/D28 -> 788 | G28: ?
B29: Huevo | C29: unidades | D29: 30 | E29: 5300 | F29: =+E29/D29 -> 176.66667 | G29: 46225
B30: Huevo (yema) | C30: unidades | D30: 30 | E30: 5300 | F30: =+E30/D30 -> 176.66667 | G30: 46225
B31: Limon (jugo de limon) | C31: kg | D31: 1 | E31: 8000 | F31: =+E31/D31 -> 8000
B32: Limon (ralladura) | C32: kg | D32: 1 | E32: 8000 | F32: =+E32/D32 -> 8000
B33: Manteca | C33: kg | D33: 10 | E33: 110066 | F33: =+E33/D33 -> 11006.6 | G33: 46219
B34: Nutella | C34: kg | D34: 6 | E34: 183952 | F34: =+E34/D34 -> 30658.667
B35: Oreo scrap | C35: kg | D35: 5 | E35: 50219 | F35: =+E35/D35 -> 10043.8 | G35: 46219
B36: Papel parafinado | C36: kg | D36: 10 | E36: 114904 | F36: =+E36/D36 -> 11490.4 | G36: 46223
B37: Polvo de hornear | C37: kg | D37: 3 | E37: 16366 | F37: =+E37/D37 -> 5455.3333 | G37: 46219
B38: Queso crema | C38: kg | D38: 4 | E38: 34900 | F38: =+E38/D38 -> 8725 | G38: ?
B39: Semillas amapolas | C39: kg | D39: 1 | E39: 13526 | F39: =+E39/D39 -> 13526 | G39: 46207
B40: Stickers | C40: unidades | D40: 3600 | E40: 62073 | F40: =+E40/D40 -> 17.2425 | G40: ?
B41: Vinagre blanco | C41: Lt | D41: 5 | E41: 5000 | F41: =+E41/D41 -> 1000 | G41: ?
...

Sheet 2) Recetas
B2: Receta | C2: Clasificacion | D2: Insumo | E2: Unidad | F2: Cantidad receta | G2: Cantidad obtenida con la receta | H2: Cantidad unitaria | I2: Costo unitario | J2: Costo parcial
B3: Brownie chocolate | C3: Brownie | D3: Manteca | E3: =+VLOOKUP(D3,'1) Planilla maestra insumos'!$B$3:$D$98,2,FALSE) -> kg | F3: 0.768 | G3: 48 | H3: =+F3/G3 -> 0.016 | I3: =+VLOOKUP(D3,Insumos,5,FALSE) -> 11006.6 | J3: =+H3*I3 -> 176.1056 | L3: 411.15
B4: Brownie chocolate | C4: Brownie | D4: Chocolate semiamargo chip | E4: =+VLOOKUP(D4,'1) Planilla maestra insumos'!$B$3:$D$98,2,FALSE) -> kg | F4: 0.504 | G4: 48 | H4: =+F4/G4 -> 0.0105 | I4: =+VLOOKUP(D4,Insumos,5,FALSE) -> 10524.5 | J4: =+H4*I4 -> 110.50725
B5: Brownie chocolate | C5: Brownie | D5: Azucar blanca | E5: =+VLOOKUP(D5,'1) Planilla maestra insumos'!$B$3:$D$98,2,FALSE) -> kg | F5: 0.88 | G5: 48 | H5: =+F5/G5 -> 0.018333333 | I5: =+VLOOKUP(D5,Insumos,5,FALSE) -> 1263.5 | J5: =+H5*I5 -> 23.164167
B6: Brownie chocolate | C6: Brownie | D6: Azucar mascabo | E6: =+VLOOKUP(D6,'1) Planilla maestra insumos'!$B$3:$D$98,2,FALSE) -> kg | F6: 0.44 | G6: 48 | H6: =+F6/G6 -> 0.0091666667 | I6: =+VLOOKUP(D6,Insumos,5,FALSE) -> 3093.8 | J6: =+H6*I6 -> 28.359833
B7: Brownie chocolate | C7: Brownie | D7: Harina 0000 | E7: =+VLOOKUP(D7,'1) Planilla maestra insumos'!$B$3:$D$98,2,FALSE) -> kg | F7: 0.55 | G7: 48 | H7: =+F7/G7 -> 0.011458333 | I7: =+VLOOKUP(D7,Insumos,5,FALSE) -> 788 | J7: =+H7*I7 -> 9.0291667
B8: Brownie chocolate | C8: Brownie | D8: Cacao amargo | E8: =+VLOOKUP(D8,'1) Planilla maestra insumos'!$B$3:$D$98,2,FALSE) -> kg | F8: 0.372 | G8: 48 | H8: =+F8/G8 -> 0.00775 | I8: =+VLOOKUP(D8,Insumos,5,FALSE) -> 23970 | J8: =+H8*I8 -> 185.7675
B9: Brownie chocolate | C9: Brownie | D9: Extracto de vainilla | E9: =+VLOOKUP(D9,'1) Planilla maestra insumos'!$B$3:$D$98,2,FALSE) -> Lt | F9: 0.015 | G9: 48 | H9: =+F9/G9 -> 0.0003125 | I9: =+VLOOKUP(D9,Insumos,5,FALSE) -> 26841.8 | J9: =+H9*I9 -> 8.3880625
B10: Brownie chocolate | C10: Brownie | D10: Huevo | E10: =+VLOOKUP(D10,'1) Planilla maestra insumos'!$B$3:$D$98,2,FALSE) -> unidades | F10: 10 | G10: 48 | H10: =+F10/G10 -> 0.20833333 | I10: =+VLOOKUP(D10,Insumos,5,FALSE) -> 176.66667 | J10: =+H10*I10 -> 36.805556
B11: Brownie oreo | C11: Brownie | D11: Manteca | E11: =+VLOOKUP(D11,'1) Planilla maestra insumos'!$B$3:$D$98,2,FALSE) -> kg | F11: 0.768 | G11: 48 | H11: =+F11/G11 -> 0.016 | I11: =+VLOOKUP(D11,Insumos,5,FALSE) -> 11006.6 | J11: =+H11*I11 -> 176.1056
B12: Brownie oreo | C12: Brownie | D12: Chocolate semiamargo chip | E12: =+VLOOKUP(D12,'1) Planilla maestra insumos'!$B$3:$D$98,2,FALSE) -> kg | F12: 0.804 | G12: 48 | H12: =+F12/G12 -> 0.01675 | I12: =+VLOOKUP(D12,Insumos,5,FALSE) -> 10524.5 | J12: =+H12*I12 -> 176.28538
B13: Brownie oreo | C13: Brownie | D13: Azucar blanca | E13: =+VLOOKUP(D13,'1) Planilla maestra insumos'!$B$3:$D$98,2,FALSE) -> kg | F13: 0.88 | G13: 48 | H13: =+F13/G13 -> 0.018333333 | I13: =+VLOOKUP(D13,Insumos,5,FALSE) -> 1263.5 | J13: =+H13*I13 -> 23.164167
B14: Brownie oreo | C14: Brownie | D14: Azucar mascabo | E14: =+VLOOKUP(D14,'1) Planilla maestra insumos'!$B$3:$D$98,2,FALSE) -> kg | F14: 0.44 | G14: 48 | H14: =+F14/G14 -> 0.0091666667 | I14: =+VLOOKUP(D14,Insumos,5,FALSE) -> 3093.8 | J14: =+H14*I14 -> 28.359833
B15: Brownie oreo | C15: Brownie | D15: Harina 0000 | E15: =+VLOOKUP(D15,'1) Planilla maestra insumos'!$B$3:$D$98,2,FALSE) -> kg | F15: 0.55 | G15: 48 | H15: =+F15/G15 -> 0.011458333 | I15: =+VLOOKUP(D15,Insumos,5,FALSE) -> 788 | J15: =+H15*I15 -> 9.0291667
... B50: Cookie red velvet rellena | C50: Cookie rellena | D50: Manteca | E50: =+VLOOKUP(D50,'1) Planilla maestra insumos'!$B$3:$D$98,2,FALSE) -> kg | F50: 0.05 | G50: 42 | H50: =+F50/G50 -> 0.0011904762 | I50: =+VLOOKUP(D50,Insumos,5,FALSE) -> 11006.6 | J50: =+H50*I50 -> 13.103095
B51: Cookie red velvet rellena | C51: Cookie rellena | D51: Almidon de maiz | E51: kg | F51: 0.04 | G51: 42 | H51: =+F51/G51 -> 0.00095238095 | I51: =+VLOOKUP(D51,Insumos,5,FALSE) -> 1600 | J51: =+H51*I51 -> 1.5238095
B52: Cookie red velvet rellena | C52: Cookie rellena | D52: Vinagre blanco | E52: =+VLOOKUP(D52,'1) Planilla maestra insumos'!$B$3:$D$98,2,FALSE) -> Lt | F52: 0.01 | G52: 42 | H52: =+F52/G52 -> 0.00023809524 | I52: =+VLOOKUP(D52,Insumos,5,FALSE) -> 1000 | J52: =+H52*I52 -> 0.23809524
B53: Cookie vainilla kinder | C53: Cookie rellena | D53: Manteca | E53: =+VLOOKUP(D53,'1) Planilla maestra insumos'!$B$3:$D$98,2,FALSE) -> kg | F53: 0.688 | G53: 37 | H53: =+F53/G53 -> 0.018594595 | I53: =+VLOOKUP(D53,Insumos,5,FALSE) -> 11006.6 | J53: =+H53*I53 -> 204.66326
B54: Cookie vainilla kinder | C54: Cookie rellena | D54: Azucar blanca | E54: =+VLOOKUP(D54,'1) Planilla maestra insumos'!$B$3:$D$98,2,FALSE) -> kg | F54: 0.984 | G54: 37 | H54: =+F54/G54 -> 0.026594595 | I54: =+VLOOKUP(D54,Insumos,5,FALSE) -> 1263.5 | J54: =+H54*I54 -> 33.60227
B55: Cookie vainilla kinder | C55: Cookie rellena | D55: Azucar mascabo | E55: =+VLOOKUP(D55,'1) Planilla maestra insumos'!$B$3:$D$98,2,FALSE) -> kg | F55: 0.432 | G55: 37 | H55: =+F55/G55 -> 0.011675676 | I55: =+VLOOKUP(D55,Insumos,5,FALSE) -> 3093.8 | J55: =+H55*I55 -> 36.122205
B56: Cookie vainilla kinder | C56: Cookie rellena | D56: Extracto de vainilla | E56: =+VLOOKUP(D56,'1) Planilla maestra insumos'!$B$3:$D$98,2,FALSE) -> Lt | F56: 0.05 | G56: 37 | H56: =+F56/G56 -> 0.0013513514 | I56: =+VLOOKUP(D56,Insumos,5,FALSE) -> 26841.8 | J56: =+H56*I56 -> 36.272703
B57: Cookie vainilla kinder | C57: Cookie rellena | D57: Huevo | E57: =+VLOOKUP(D57,'1) Planilla maestra insumos'!$B$3:$D$98,2,FALSE) -> unidades | F57: 7 | G57: 37 | H57: =+F57/G57 -> 0.18918919 | I57: =+VLOOKUP(D57,Insumos,5,FALSE) -> 176.66667 | J57: =+H57*I57 -> 33.423423
B58: Cookie vainilla kinder | C58: Cookie rellena | D58: Harina 0000 | E58: =+VLOOKUP(D58,'1) Planilla maestra insumos'!$B$3:$D$98,2,FALSE) -> kg | F58: 1.188 | G58: 37 | H58: =+F58/G58 -> 0.032108108 | I58: =+VLOOKUP(D58,Insumos,5,FALSE) -> 788 | J58: =+H58*I58 -> 25.301189
B59: Cookie vainilla kinder | C59: Cookie rellena | D59: Harina 000 | E59: =+VLOOKUP(D59,'1) Planilla maestra insumos'!$B$3:$D$98,2,FALSE) -> kg | F59: 0.792 | G59: 37 | H59: =+F59/G59 -> 0.021405405 | I59: =+VLOOKUP(D59,Insumos,5,FALSE) -> 692 | J59: =+H59*I59 -> 14.812541
B60: Cookie vainilla kinder | C60: Cookie rellena | D60: Polvo de hornear | E60: =+VLOOKUP(D60,'1) Planilla maestra insumos'!$B$3:$D$98,2,FALSE) -> kg | F60: 0.03 | G60: 37 | H60: =+F60/G60 -> 0.00081081081 | I60: =+VLOOKUP(D60,Insumos,5,FALSE) -> 5455.3333 | J60: =+H60*I60 -> 4.4232432
B61: Cookie vainilla kinder | C61: Cookie rellena | D61: Bicarbonato | E61: =+VLOOKUP(D61,'1) Planilla maestra insumos'!$B$3:$D$98,2,FALSE) -> kg | F61: 0.01 | G61: 37 | H61: =+F61/G61 -> 0.00027027027 | I61: =+VLOOKUP(D61,Insumos,5,FALSE) -> 6000 | J61: =+H61*I61 -> 1.6216216
B62: Cookie vainilla kinder | C62: Cookie rellena | D62: Barra de kinder | E62: =+VLOOKUP(D62,'1) Planilla maestra insumos'!$B$3:$D$98,2,FALSE) -> tabla | F62: 1 | G62: 1 | H62: =+F62/G62 -> 1 | I62: =+VLOOKUP(D62,Insumos,5,FALSE) -> 521.375 | J62: =+H62*I62 -> 521.375
B63: Cookie vainilla kinder | C63: Cookie rellena | D63: Nutella | E63: =+VLOOKUP(D63,'1) Planilla maestra insumos'!$B$3:$D$98,2,FALSE) -> kg | F63: 0.018 | G63: 1 | H63: =+F63/G63 -> 0.018 | I63: =+VLOOKUP(D63,Insumos,5,FALSE) -> 30658.667 | J63: =+H63*I63 -> 551.856
... B116: Cookie limon clasica | C116: Cookie clasica | D116: Bicarbonato | E116: =+VLOOKUP(D116,'1) Planilla maestra insumos'!$B$3:$D$98,2,FALSE) -> kg | F116: 0.01 | G116: 117 | H116: =+F116/G116 -> 8.5470085e-05 | I116: =+VLOOKUP(D116,Insumos,5,FALSE) -> 6000 | J116: =+H116*I116 -> 0.51282051
B117: Cookie limon clasica | C117: Cookie clasica | D117: Limon (ralladura) | E117: =+VLOOKUP(D117,'1) Planilla maestra insumos'!$B$3:$D$98,2,FALSE) -> kg | F117: =240/1000 -> 0.24 | G117: 117 | H117: =+F117/G117 -> 0.0020512821 | I117: =+VLOOKUP(D117,Insumos,5,FALSE) -> 8000 | J117: =+H117*I117 -> 16.410256
B118: Cookie limon clasica | C118: Cookie clasica | D118: Semillas amapolas | E118: =+VLOOKUP(D118,'1) Planilla maestra insumos'!$B$3:$D$98,2,FALSE) -> kg | F118: 0.064 | G118: 117 | H118: =+F118/G118 -> 0.00054700855 | I118: =+VLOOKUP(D118,Insumos,5,FALSE) -> 13526 | J118: =+H118*I118 -> 7.3988376
B119: Cookie red velvet clasica | C119: Cookie clasica | D119: Manteca | E119: =+VLOOKUP(D119,'1) Planilla maestra insumos'!$B$3:$D$98,2,FALSE) -> kg | F119: 0.76 | G119: 117 | H119: =+F119/G119 -> 0.0064957265 | I119: =+VLOOKUP(D119,Insumos,5,FALSE) -> 11006.6 | J119: =+H119*I119 -> 71.495863
B120: Cookie red velvet clasica | C120: Cookie clasica | D120: Azucar blanca | E120: =+VLOOKUP(D120,'1) Planilla maestra insumos'!$B$3:$D$98,2,FALSE) -> kg | F120: 0.944 | G120: 117 | H120: =+F120/G120 -> 0.0080683761 | I120: =+VLOOKUP(D120,Insumos,5,FALSE) -> 1263.5 | J120: =+H120*I120 -> 10.194393
B121: Cookie red velvet clasica | C121: Cookie clasica | D121: Azucar mascabo | E121: =+VLOOKUP(D121,'1) Planilla maestra insumos'!$B$3:$D$98,2,FALSE) -> kg | F121: 0.4 | G121: 117 | H121: =+F121/G121 -> 0.0034188034 | I121: =+VLOOKUP(D121,Insumos,5,FALSE) -> 3093.8 | J121: =+H121*I121 -> 10.577094
B122: Cookie red velvet clasica | C122: Cookie clasica | D122: Huevo | E122: =+VLOOKUP(D122,'1) Planilla maestra insumos'!$B$3:$D$98,2,FALSE) -> unidades | F122: 8 | G122: 117 | H122: =+F122/G122 -> 0.068376068 | I122: =+VLOOKUP(D122,Insumos,5,FALSE) -> 176.66667 | J122: =+H122*I122 -> 12.079772
B123: Cookie red velvet clasica | C123: Cookie clasica | D123: Harina 0000 | E123: =+VLOOKUP(D123,'1) Planilla maestra insumos'!$B$3:$D$98,2,FALSE) -> kg | F123: 1 | G123: 117 | H123: =+F123/G123 -> 0.0085470085 | I123: =+VLOOKUP(D123,Insumos,5,FALSE) -> 788 | J123: =+H123*I123 -> 6.7350427
B124: Cookie red velvet clasica | C124: Cookie clasica | D124: Harina 000 | E124: =+VLOOKUP(D124,'1) Planilla maestra insumos'!$B$3:$D$98,2,FALSE) -> kg | F124: 0.63 | G124: 117 | H124: =+F124/G124 -> 0.0053846154 | I124: =+VLOOKUP(D124,Insumos,5,FALSE) -> 692 | J124: =+H124*I124 -> 3.7261538
B125: Cookie red velvet clasica | C125: Cookie clasica | D125: Cacao amargo | E125: =+VLOOKUP(D125,'1) Planilla maestra insumos'!$B$3:$D$98,2,FALSE) -> kg | F125: 0.08 | G125: 117 | H125: =+F125/G125 -> 0.00068376068 | I125: =+VLOOKUP(D125,Insumos,5,FALSE) -> 23970 | J125: =+H125*I125 -> 16.389744
B126: Cookie red velvet clasica | C126: Cookie clasica | D126: Bicarbonato | E126: =+VLOOKUP(D126,'1) Planilla maestra insumos'!$B$3:$D$98,2,FALSE) -> kg | F126: 0.012 | G126: 117 | H126: =+F126/G126 -> 0.0001025641 | I126: =+VLOOKUP(D126,Insumos,5,FALSE) -> 6000 | J126: =+H126*I126 -> 0.61538462
B127: Cookie red velvet clasica | C127: Cookie clasica | D127: Vinagre blanco | E127: =+VLOOKUP(D127,'1) Planilla maestra insumos'!$B$3:$D$98,2,FALSE) -> Lt | F127: 0.009 | G127: 117 | H127: =+F127/G127 -> 7.6923077e-05 | I127: =+VLOOKUP(D127,Insumos,5,FALSE) -> 1000 | J127: =+H127*I127 -> 0.076923077
...

Sheet 3) costo mp
B3: Etiquetas de fila | C3: Suma de Costo parcial
B4: Brownie chocolate | C4: 578.12713
B5: Brownie oreo | C5: 764.07659
B6: Brownie red velvet | C6: 539.65357
B7: Cookie chip clasica | C7: 148.49956
B8: Cookie Chocotorta | C8: 589.23391
B9: Cookie Franui rellena | C9: 905.60151
B10: Cookie limon clasica | C10: 147.28883
B11: Cookie limon rellena | C11: 561.37585
B12: Cookie oreo clasica | C12: 194.51099
B13: Cookie oreo rellena | C13: 750.96462
B14: Cookie red velvet clasica | C14: 178.04895
B15: Cookie red velvet rellena | C15: 630.08327
... B20: Total general | C20: 10987.014

Sheet 4) Packaging
B3: Descripcion producto | C3: Insumos | D3: Unidad | E3: Cantidad | F3: Costo parcial | G3: Costo total
B4: Combo mesa dulce | C4: Caja grande | D4: =+VLOOKUP(C4,Insumos,2,FALSE) -> unidades | E4: 1 | F4: =+VLOOKUP(C4,Insumos,5,FALSE)*E4 -> 174.685 | G4: =+SUM(F4:F6) -> 216.05734
C5: Stickers | D5: unidades | E5: 1 | F5: =+VLOOKUP(C5,Insumos,5,FALSE)*E5 -> 17.2425
C6: Papel parafinado | D6: =+VLOOKUP(C6,Insumos,2,FALSE) -> kg | E6: =2.1/1000 -> 0.0021 | F6: =+VLOOKUP(C6,Insumos,5,FALSE)*E6 -> 24.12984
B7: Combo familiar | C7: Caja grande | D7: =+VLOOKUP(C7,Insumos,2,FALSE) -> unidades | E7: 2 | F7: =+VLOOKUP(C7,Insumos,5,FALSE)*E7 -> 349.37 | G7: =+SUM(F7:F9) -> 432.11468
C8: Stickers | D8: unidades | E8: 2 | F8: =+VLOOKUP(C8,Insumos,5,FALSE)*E8 -> 34.485
C9: Papel parafinado | D9: =+VLOOKUP(C9,Insumos,2,FALSE) -> kg | E9: =2.1*2/1000 -> 0.0042 | F9: =+VLOOKUP(C9,Insumos,5,FALSE)*E9 -> 48.25968
B10: Combo brownies x4 | C10: Caja grande | D10: =+VLOOKUP(C10,Insumos,2,FALSE) -> unidades | E10: 1 | F10: =+VLOOKUP(C10,Insumos,5,FALSE)*E10 -> 174.685 | G10: =+SUM(F10:F12) -> 216.05734
C11: Stickers | D11: unidades | E11: 1 | F11: =+VLOOKUP(C11,Insumos,5,FALSE)*E11 -> 17.2425
C12: Papel parafinado | D12: =+VLOOKUP(C12,Insumos,2,FALSE) -> kg | E12: =2.1/1000 -> 0.0021 | F12: =+VLOOKUP(C12,Insumos,5,FALSE)*E12 -> 24.12984
B13: Combo brownies x6 | C13: Caja grande | D13: =+VLOOKUP(C13,Insumos,2,FALSE) -> unidades | E13: 1 | F13: =+VLOOKUP(C13,Insumos,5,FALSE)*E13 -> 174.685 | G13: =+SUM(F13:F15) -> 216.05734
C14: Stickers | D14: unidades | E14: 1 | F14: =+VLOOKUP(C14,Insumos,5,FALSE)*E14 -> 17.2425
C15: Papel parafinado | D15: =+VLOOKUP(C15,Insumos,2,FALSE) -> kg | E15: =2.1/1000 -> 0.0021 | F15: =+VLOOKUP(C15,Insumos,5,FALSE)*E15 -> 24.12984
B16: Combo clasicas x6 | C16: caja chica | D16: =+VLOOKUP(C16,Insumos,2,FALSE) -> unidades | E16: 1 | F16: =+VLOOKUP(C16,Insumos,5,FALSE)*E16 -> 108 | G16: =+SUM(F16:F18) -> 149.37234
C17: Stickers | D17: unidades | E17: 1 | F17: =+VLOOKUP(C17,Insumos,5,FALSE)*E17 -> 17.2425
C18: Papel parafinado | D18: =+VLOOKUP(C18,Insumos,2,FALSE) -> kg | E18: =2.1/1000 -> 0.0021 | F18: =+VLOOKUP(C18,Insumos,5,FALSE)*E18 -> 24.12984
B19: Combo clasicas x12 | C19: caja grande | D19: =+VLOOKUP(C19,Insumos,2,FALSE) -> unidades | E19: 1 | F19: =+VLOOKUP(C19,Insumos,5,FALSE)*E19 -> 174.685 | G19: =+SUM(F19:F21) -> 216.05734
C20: Stickers | D20: unidades | E20: 1 | F20: =+VLOOKUP(C20,Insumos,5,FALSE)*E20 -> 17.2425
C21: Papel parafinado | D21: =+VLOOKUP(C21,Insumos,2,FALSE) -> kg | E21: =2.1/1000 -> 0.0021 | F21: =+VLOOKUP(C21,Insumos,5,FALSE)*E21 -> 24.12984
B22: Combo rellenas x3 | C22: Caja grande | D22: =+VLOOKUP(C22,Insumos,2,FALSE) -> unidades | E22: 1 | F22: =+VLOOKUP(C22,Insumos,5,FALSE)*E22 -> 174.685 | G22: =+SUM(F22:F24) -> 216.05734
C23: Stickers | D23: unidades | E23: 1 | F23: =+VLOOKUP(C23,Insumos,5,FALSE)*E23 -> 17.2425
C24: Papel parafinado | D24: =+VLOOKUP(C24,Insumos,2,FALSE) -> kg | E24: =2.1/1000 -> 0.0021 | F24: =+VLOOKUP(C24,Insumos,5,FALSE)*E24 -> 24.12984
B25: Cookie rellena x1 | C25: caja chica | D25: =+VLOOKUP(C25,Insumos,2,FALSE) -> unidades | E25: 1 | F25: =+VLOOKUP(C25,Insumos,5,FALSE)*E25 -> 108 | G25: =+SUM(F25:F27) -> 149.37234
C26: Stickers | D26: unidades | E26: 1 | F26: =+VLOOKUP(C26,Insumos,5,FALSE)*E26 -> 17.2425
C27: Papel parafinado | D27: =+VLOOKUP(C27,Insumos,2,FALSE) -> kg | E27: =2.1/1000 -> 0.0021 | F27: =+VLOOKUP(C27,Insumos,5,FALSE)*E27 -> 24.12984
B28: Cookie clasica x1 | C28: caja chica | D28: =+VLOOKUP(C28,Insumos,2,FALSE) -> unidades | E28: 1 | F28: =+VLOOKUP(C28,Insumos,5,FALSE)*E28 -> 108 | G28: =+SUM(F28:F30) -> 149.37234
C29: Stickers | D29: unidades | E29: 1 | F29: =+VLOOKUP(C29,Insumos,5,FALSE)*E29 -> 17.2425
C30: Papel parafinado | D30: =+VLOOKUP(C30,Insumos,2,FALSE) -> kg | E30: =2.1/1000 -> 0.0021 | F30: =+VLOOKUP(C30,Insumos,5,FALSE)*E30 -> 24.12984
B31: brownie x1 | C31: caja chica | D31: =+VLOOKUP(C31,Insumos,2,FALSE) -> unidades | E31: 1 | F31: =+VLOOKUP(C31,Insumos,5,FALSE)*E31 -> 108 | G31: =+SUM(F31:F33) -> 149.37234
C32: Stickers | D32: unidades | E32: 1 | F32: =+VLOOKUP(C32,Insumos,5,FALSE)*E32 -> 17.2425
C33: Papel parafinado | D33: =+VLOOKUP(C33,Insumos,2,FALSE) -> kg | E33: =2.1/1000 -> 0.0021 | F33: =+VLOOKUP(C33,Insumos,5,FALSE)*E33 -> 24.12984
B34: Combo entre dos | C34: Caja grande | D34: =+VLOOKUP(C34,Insumos,2,FALSE) -> unidades | E34: 1 | F34: =+VLOOKUP(C34,Insumos,5,FALSE)*E34 -> 174.685 | G34: =+SUM(F34:F36) -> 216.05734
C35: Stickers | D35: unidades | E35: 1 | F35: =+VLOOKUP(C35,Insumos,5,FALSE)*E35 -> 17.2425
C36: Papel parafinado | D36: =+VLOOKUP(C36,Insumos,2,FALSE) -> kg | E36: =2.1/1000 -> 0.0021 | F36: =+VLOOKUP(C36,Insumos,5,FALSE)*E36 -> 24.12984
B37: Combo para sorprender | C37: Caja grande | D37: =+VLOOKUP(C37,Insumos,2,FALSE) -> unidades | E37: 1 | F37: =+VLOOKUP(C37,Insumos,5,FALSE)*E37 -> 174.685 | G37: =+SUM(F37:F39) -> 216.05734
C38: Stickers | D38: unidades | E38: 1 | F38: =+VLOOKUP(C38,Insumos,5,FALSE)*E38 -> 17.2425
C39: Papel parafinado | D39: =+VLOOKUP(C39,Insumos,2,FALSE) -> kg | E39: =2.1/1000 -> 0.0021 | F39: =+VLOOKUP(C39,Insumos,5,FALSE)*E39 -> 24.12984
B40: Combo para alegrar | C40: Caja grande | D40: =+VLOOKUP(C40,Insumos,2,FALSE) -> unidades | E40: 1 | F40: =+VLOOKUP(C40,Insumos,5,FALSE)*E40 -> 174.685 | G40: =+SUM(F40:F42) -> 216.05734
C41: Stickers | D41: unidades | E41: 1 | F41: =+VLOOKUP(C41,Insumos,5,FALSE)*E41 -> 17.2425
C42: Papel parafinado | D42: =+VLOOKUP(C42,Insumos,2,FALSE) -> kg | E42: =2.1/1000 -> 0.0021 | F42: =+VLOOKUP(C42,Insumos,5,FALSE)*E42 -> 24.12984
...

Sheet 5) Costo final variables
B2: Descripcion producto | C2: Detalle | D2: Costo del producto | E2: Cantidad | F2: Costo x producto | G2: Costo packaging | H2: Costo total | I2: Precio de carta actual | J2: Utilidad | K2: %
B3: Combo mesa dulce | C3: Cookie chip clasica | D3: =+IFERROR(VLOOKUP(C3,Prodfinales,2,FALSE),"") | E3: 2 | F3: =+IFERROR(D3*E3,"") | G3: =+IFERROR(VLOOKUP(B3,Pack,6,FALSE),"") | H3: =+IFERROR(SUM(F3:F9)+G3,"") | I3: 10000 | J3: =+I3-H3 -> #VALUE! | K3: =(J3/I3) -> #VALUE!
C4: Cookie red velvet clasica | D4: =+IFERROR(VLOOKUP(C4,Prodfinales,2,FALSE),"") | E4: 2 | F4: =+IFERROR(D4*E4,"")
C5: Cookie oreo clasica | D5: =+IFERROR(VLOOKUP(C5,Prodfinales,2,FALSE),"") | E5: 2 | F5: =+IFERROR(D5*E5,"")
C6: Brownie chocolate | D6: =+IFERROR(VLOOKUP(C6,Prodfinales,2,FALSE),"") | E6: 2 | F6: =+IFERROR(D6*E6,"")
C7: Brownie oreo | D7: =+IFERROR(VLOOKUP(C7,Prodfinales,2,FALSE),"") | E7: 2 | F7: =+IFERROR(D7*E7,"")
D8: =+IFERROR(VLOOKUP(C8,Prodfinales,2,FALSE),"") | F8: =+IFERROR(D8*E8,"")
D9: =+IFERROR(VLOOKUP(C9,Prodfinales,2,FALSE),"") | F9: =+IFERROR(D9*E9,"")
B10: Descripcion producto | C10: Detalle | D10: Costo del producto | E10: Cantidad | F10: Costo x producto | G10: Costo packaging | H10: Costo total | I10: Precio actual | J10: Utilidad | K10: %
B11: Combo familiar | C11: Cookie limon clasica | D11: =+IFERROR(VLOOKUP(C11,Prodfinales,2,FALSE),"") | E11: 3 | F11: =+IFERROR(D11*E11,"") | G11: =+IFERROR(VLOOKUP(B11,Pack,6,FALSE),"") | H11: =+IFERROR(SUM(F11:F18)+G11,"") | I11: 16000 | J11: =+I11-H11 -> #VALUE! | K11: =(J11/I11) -> #VALUE!
C12: Cookie oreo clasica | D12: =+IFERROR(VLOOKUP(C12,Prodfinales,2,FALSE),"") | E12: 3 | F12: =+IFERROR(D12*E12,"")
C13: Cookie red velvet clasica | D13: =+IFERROR(VLOOKUP(C13,Prodfinales,2,FALSE),"") | E13: 3 | F13: =+IFERROR(D13*E13,"")
C14: Cookie chip clasica | D14: =+IFERROR(VLOOKUP(C14,Prodfinales,2,FALSE),"") | E14: 3 | F14: =+IFERROR(D14*E14,"")
C15: Brownie oreo | D15: =+IFERROR(VLOOKUP(C15,Prodfinales,2,FALSE),"") | E15: 2 | F15: =+IFERROR(D15*E15,"")
C16: Brownie chocolate | D16: =+IFERROR(VLOOKUP(C16,Prodfinales,2,FALSE),"") | E16: 2 | F16: =+IFERROR(D16*E16,"")
C17: Brownie red velvet | D17: =+IFERROR(VLOOKUP(C17,Prodfinales,2,FALSE),"") | E17: 2 | F17: =+IFERROR(D17*E17,"")
D18: =+IFERROR(VLOOKUP(C18,Prodfinales,2,FALSE),"") | F18: =+IFERROR(D18*E18,"")
B19: Descripcion producto | C19: Detalle | D19: Costo del producto | E19: Cantidad | F19: Costo x producto | G19: Costo packaging | H19: Costo total | I19: Precio actual | J19: Utilidad | K19: %
B20: Combo rellenas x3 | C20: Cookie vainilla bon o bon | D20: =+IFERROR(VLOOKUP(C20,Prodfinales,2,FALSE),"") | E20: 1 | F20: =+IFERROR(D20*E20,"") | G20: =+IFERROR(VLOOKUP(B20,Pack,6,FALSE),"") | H20: =+IFERROR(SUM(F20:F22)+G20,"") | I20: 10000 | J20: =+I20-H20 -> #VALUE! | K20: =(J20/I20) -> #VALUE!
C21: Cookie vainilla ferrero | D21: =+IFERROR(VLOOKUP(C21,Prodfinales,2,FALSE),"") | E21: 1 | F21: =+IFERROR(D21*E21,"")
C22: Cookie vainilla kinder | D22: =+IFERROR(VLOOKUP(C22,Prodfinales,2,FALSE),"") | E22: 1 | F22: =+IFERROR(D22*E22,"")
B23: Descripcion producto | C23: Detalle | D23: Costo del producto | E23: Cantidad | F23: Costo x producto | G23: Costo packaging | H23: Costo total | I23: Precio actual | J23: Utilidad | K23: %
B24: Combo brownies x6 | C24: Brownie red velvet | D24: =+IFERROR(VLOOKUP(C24,Prodfinales,2,FALSE),"") | E24: 2 | F24: =+IFERROR(D24*E24,"") | G24: =+IFERROR(VLOOKUP(B24,Pack,6,FALSE),"") | H24: =+IFERROR(SUM(F24:F26)+G24,"") | I24: 8500 | J24: =+I24-H24 -> #VALUE! | K24: =(J24/I24) -> #VALUE!
C25: Brownie oreo | D25: =+IFERROR(VLOOKUP(C25,Prodfinales,2,FALSE),"") | E25: 2 | F25: =+IFERROR(D25*E25,"")
C26: Brownie chocolate | D26: =+IFERROR(VLOOKUP(C26,Prodfinales,2,FALSE),"") | E26: 2 | F26: =+IFERROR(D26*E26,"")
B27: Descripcion producto | C27: Detalle | D27: Costo del producto | E27: Cantidad | F27: Costo x producto | G27: Costo packaging | H27: Costo total | I27: Precio actual | J27: Utilidad | K27: %
B28: Combo clasicas x12 | C28: Cookie chip clasica | D28: =+IFERROR(VLOOKUP(C28,Prodfinales,2,FALSE),"") | E28: 3 | F28: =+IFERROR(D28*E28,"") | G28: =+IFERROR(VLOOKUP(B28,Pack,6,FALSE),"") | H28: =+IFERROR(SUM(F28:F31)+G28,"") | I28: 8500 | J28: =+I28-H28 -> #VALUE! | K28: =(J28/I28) -> #VALUE!
C29: Cookie limon clasica | D29: =+IFERROR(VLOOKUP(C29,Prodfinales,2,FALSE),"") | E29: 3 | F29: =+IFERROR(D29*E29,"")
C30: Cookie oreo clasica | D30: =+IFERROR(VLOOKUP(C30,Prodfinales,2,FALSE),"") | E30: 3 | F30: =+IFERROR(D30*E30,"")
C31: Cookie red velvet clasica | D31: =+IFERROR(VLOOKUP(C31,Prodfinales,2,FALSE),"") | E31: 3 | F31: =+IFERROR(D31*E31,"")
B32: Descripcion producto | C32: Detalle | D32: Costo del producto | E32: Cantidad | F32: Costo x producto | G32: Costo packaging | H32: Costo total | I32: Precio actual | J32: Utilidad | K32: %
B33: Combo clasicas x6 | C33: Cookie chip clasica | D33: =+IFERROR(VLOOKUP(C33,Prodfinales,2,FALSE),"") | E33: 2 | F33: =+IFERROR(D33*E33,"") | G33: =+IFERROR(VLOOKUP(B33,Pack,6,FALSE),"") | H33: =+IFERROR(SUM(F33:F35)+G33,"") | I33: 4500 | J33: =+I33-H33 -> #VALUE! | K33: =(J33/I33) -> #VALUE!
C34: Cookie red velvet clasica | D34: =+IFERROR(VLOOKUP(C34,Prodfinales,2,FALSE),"") | E34: 2 | F34: =+IFERROR(D34*E34,"")
C35: Cookie oreo clasica | D35: =+IFERROR(VLOOKUP(C35,Prodfinales,2,FALSE),"") | E35: 2 | F35: =+IFERROR(D35*E35,"")
B36: Descripcion producto | C36: Detalle | D36: Costo del producto | E36: Cantidad | F36: Costo x producto | G36: Costo packaging | H36: Costo total | I36: Precio actual | J36: Utilidad | K36: %
B37: Cookie rellena x1 | C37: Cookie vainilla ferrero | D37: =+IFERROR(VLOOKUP(C37,Prodfinales,2,FALSE),"") | E37: 1 | F37: =+IFERROR(D37*E37,"") | G37: =+IFERROR(VLOOKUP(B37,Pack,6,FALSE),"") | H37: =+IFERROR(SUM(F37)+G37,"") | I37: 3500 | J37: =+I37-H37 -> #VALUE! | K37: =(J37/I37) -> #VALUE!
B38: Descripcion producto | C38: Detalle | D38: Costo del producto | E38: Cantidad | F38: Costo x producto | G38: Costo packaging | H38: Costo total | I38: Precio actual | J38: Utilidad | K38: %
B39: Cookie rellena x1 | C39: Cookie vainilla bon o bon | D39: =+IFERROR(VLOOKUP(C39,Prodfinales,2,FALSE),"") | E39: 1 | F39: =+IFERROR(D39*E39,"") | G39: =+IFERROR(VLOOKUP(B39,Pack,6,FALSE),"") | H39: =+IFERROR(SUM(F39)+G39,"") | I39: 3500 | J39: =+I39-H39 -> #VALUE! | K39: =(J39/I39) -> #VALUE!
B40: Descripcion producto | C40: Detalle | D40: Costo del producto | E40: Cantidad | F40: Costo x producto | G40: Costo packaging | H40: Costo total | I40: Precio actual | J40: Utilidad | K40: %
B41: Cookie rellena x1 | C41: Cookie vainilla kinder | D41: =+IFERROR(VLOOKUP(C41,Prodfinales,2,FALSE),"") | E41: 1 | F41: =+IFERROR(D41*E41,"") | G41: =+IFERROR(VLOOKUP(B41,Pack,6,FALSE),"") | H41: =+IFERROR(SUM(F41)+G41,"") | I41: 3500 | J41: =+I41-H41 -> #VALUE! | K41: =(J41/I41) -> #VALUE!
...

Sheet 5) Costo total
B2: Descripcion producto | C2: Detalle | D2: Costo del producto | E2: Cantidad | F2: Costo x producto | G2: Costo packaging | H2: Costo total | I2: Carta actual | J2: Precio carta febrero 2026 | K2: Precio carta: Costo variable x2,5 | L2: Precio carta actual + 10% | M2: Precios carta nueva | N2: Utilidad carta actual | O2: Diferencia | P2: utilidad en%
B3: brownie x1 | C3: Brownie chocolate | D3: =+IFERROR(VLOOKUP(C3,'3) costo mp'!$B$4:$C$19,2,FALSE),"") -> 578.12713 | E3: 1 | F3: =+IFERROR(D3*E3,"") -> 578.12713 | G3: =+IFERROR(VLOOKUP(B3,Packaging,6,FALSE),"") -> 149.37234 | H3: =+IFERROR(SUM(F3)+G3,"") -> 727.49947 | J3: 2000 | K3: =+H3*2.5 -> 1818.7487 | L3: =+J3*1.1 -> 2200 | M3: =+IF(L3>K3,L3,K3) -> 2200 | N3: =+J3-H3 -> 1272.5005 | O3: =+M3-J3 -> 200 | P3: =(N3/J3) -> 0.63625026
B4: Combo brownies x6 | C4: Brownie red velvet | D4: =+IFERROR(VLOOKUP(C4,'3) costo mp'!$B$4:$C$19,2,FALSE),"") -> 539.65357 | E4: 1 | F4: =+IFERROR(D4*E4,"") -> 539.65357 | G4: =+IFERROR(VLOOKUP(B4,Packaging,6,FALSE),"") -> 216.05734 | H4: =+IFERROR(SUM(F4:F6)+G4,"") -> 2676.0418 | J4: 8500 | K4: =+H4*2.5 -> 6690.1044 | L4: =+J4*1.1 -> 9350 | M4: =+IF(L4>K4,L4,K4) -> 9350 | N4: =+J4-H4 -> 5823.9582 | O4: =+M4-J4 -> 850 | P4: =(N4/J4) -> 0.68517156
B5: Combo brownies x6 | C5: Brownie oreo | D5: =+IFERROR(VLOOKUP(C5,'3) costo mp'!$B$4:$C$19,2,FALSE),"") -> 764.07659 | E5: 1 | F5: =+IFERROR(D5*E5,"") -> 764.07659 | K5: =+H5*2.5 -> 0 | L5: =+J5*1.1 -> 0 | M5: =+IF(L5>K5,L5,K5) -> 0 | O5: =+M5-J5 -> 0
B6: Combo brownies x6 | C6: Brownie chocolate | D6: =+IFERROR(VLOOKUP(C6,'3) costo mp'!$B$4:$C$19,2,FALSE),"") -> 578.12713 | E6: 2 | F6: =+IFERROR(D6*E6,"") -> 1156.2543 | K6: =+H6*2.5 -> 0 | L6: =+J6*1.1 -> 0 | M6: =+IF(L6>K6,L6,K6) -> 0 | O6: =+M6-J6 -> 0
B7: Combo clasicas x12 | C7: Cookie chip clasica | D7: =+IFERROR(VLOOKUP(C7,'3) costo mp'!$B$4:$C$19,2,FALSE),"") -> 148.49956 | E7: 5 | F7: =+IFERROR(D7*E7,"") -> 742.49779 | G7: =+IFERROR(VLOOKUP(B7,Packaging,6,FALSE),"") -> 216.05734 | H7: =+IFERROR(SUM(F7:F10)+G7,"") -> 2223.5238 | J7: 8500 | K7: =+H7*2.5 -> 5558.8095 | L7: =+J7*1.1 -> 9350 | M7: =+IF(L7>K7,L7,K7) -> 9350 | N7: =+J7-H7 -> 6276.4762 | O7: =+M7-J7 -> 850 | P7: =(N7/J7) -> 0.73840897
B8: Combo clasicas x12 | C8: Cookie limon clasica | D8: =+IFERROR(VLOOKUP(C8,'3) costo mp'!$B$4:$C$19,2,FALSE),"") -> 147.28883 | E8: 1 | F8: =+IFERROR(D8*E8,"") -> 147.28883 | K8: =+H8*2.5 -> 0 | L8: =+J8*1.1 -> 0 | M8: =+IF(L8>K8,L8,K8) -> 0 | O8: =+M8-J8 -> 0
B9: Combo clasicas x12 | C9: Cookie oreo clasica | D9: =+IFERROR(VLOOKUP(C9,'3) costo mp'!$B$4:$C$19,2,FALSE),"") -> 194.51099 | E9: 3 | F9: =+IFERROR(D9*E9,"") -> 583.53298 | K9: =+H9*2.5 -> 0 | L9: =+J9*1.1 -> 0 | M9: =+IF(L9>K9,L9,K9) -> 0 | O9: =+M9-J9 -> 0
B10: Combo clasicas x12 | C10: Cookie red velvet clasica | D10: =+IFERROR(VLOOKUP(C10,'3) costo mp'!$B$4:$C$19,2,FALSE),"") -> 178.04895 | E10: 3 | F10: =+IFERROR(D10*E10,"") -> 534.14685 | K10: =+H10*2.5 -> 0 | L10: =+J10*1.1 -> 0 | M10: =+IF(L10>K10,L10,K10) -> 0 | O10: =+M10-J10 -> 0
B11: Combo clasicas x6 | C11: Cookie chip clasica | D11: =+IFERROR(VLOOKUP(C11,'3) costo mp'!$B$4:$C$19,2,FALSE),"") -> 148.49956 | E11: 2 | F11: =+IFERROR(D11*E11,"") -> 296.99912 | G11: =+IFERROR(VLOOKUP(B11,Packaging,6,FALSE),"") -> 149.37234 | H11: =+IFERROR(SUM(F11:F13)+G11,"") -> 1191.4913 | J11: 4500 | K11: =+H11*2.5 -> 2978.7283 | L11: =+J11*1.1 -> 4950 | M11: =+IF(L11>K11,L11,K11) -> 4950 | N11: =+J11-H11 -> 3308.5087 | O11: =+M11-J11 -> 450 | P11: =(N11/J11) -> 0.73522415
B12: Combo clasicas x6 | C12: Cookie red velvet clasica | D12: =+IFERROR(VLOOKUP(C12,'3) costo mp'!$B$4:$C$19,2,FALSE),"") -> 178.04895 | E12: 2 | F12: =+IFERROR(D12*E12,"") -> 356.0979 | K12: =+H12*2.5 -> 0 | L12: =+J12*1.1 -> 0 | M12: =+IF(L12>K12,L12,K12) -> 0 | O12: =+M12-J12 -> 0
B13: Combo clasicas x6 | C13: Cookie oreo clasica | D13: =+IFERROR(VLOOKUP(C13,'3) costo mp'!$B$4:$C$19,2,FALSE),"") -> 194.51099 | E13: 2 | F13: =+IFERROR(D13*E13,"") -> 389.02198 | K13: =+H13*2.5 -> 0 | L13: =+J13*1.1 -> 0 | M13: =+IF(L13>K13,L13,K13) -> 0 | O13: =+M13-J13 -> 0
B14: Combo familiar | C14: Cookie limon clasica | D14: =+IFERROR(VLOOKUP(C14,'3) costo mp'!$B$4:$C$19,2,FALSE),"") -> 147.28883 | E14: 3 | F14: =+IFERROR(D14*E14,"") -> 441.86649 | G14: =+IFERROR(VLOOKUP(B14,Packaging,6,FALSE),"") -> 432.11468 | H14: =+IFERROR(SUM(F14:F20)+G14,"") -> 6200.8743 | J14: 16000 | K14: =+H14*2.5 -> 15502.186 | L14: =+J14*1.1 -> 17600 | M14: =+IF(L14>K14,L14,K14) -> 17600 | N14: =+J14-H14 -> 9799.1257 | O14: =+M14-J14 -> 1600 | P14: =(N14/J14) -> 0.61244536
B15: Combo familiar | C15: Cookie oreo clasica | D15: =+IFERROR(VLOOKUP(C15,'3) costo mp'!$B$4:$C$19,2,FALSE),"") -> 194.51099 | E15: 3 | F15: =+IFERROR(D15*E15,"") -> 583.53298 | K15: =+H15*2.5 -> 0 | L15: =+J15*1.1 -> 0 | M15: =+IF(L15>K15,L15,K15) -> 0 | O15: =+M15-J15 -> 0
B16: Combo familiar | C16: Cookie red velvet clasica | D16: =+IFERROR(VLOOKUP(C16,'3) costo mp'!$B$4:$C$19,2,FALSE),"") -> 178.04895 | E16: 3 | F16: =+IFERROR(D16*E16,"") -> 534.14685 | K16: =+H16*2.5 -> 0 | L16: =+J16*1.1 -> 0 | M16: =+IF(L16>K16,L16,K16) -> 0 | O16: =+M16-J16 -> 0
B17: Combo familiar | C17: Cookie chip clasica | D17: =+IFERROR(VLOOKUP(C17,'3) costo mp'!$B$4:$C$19,2,FALSE),"") -> 148.49956 | E17: 3 | F17: =+IFERROR(D17*E17,"") -> 445.49868 | K17: =+H17*2.5 -> 0 | L17: =+J17*1.1 -> 0 | M17: =+IF(L17>K17,L17,K17) -> 0 | O17: =+M17-J17 -> 0
B18: Combo familiar | C18: Brownie oreo | D18: =+IFERROR(VLOOKUP(C18,'3) costo mp'!$B$4:$C$19,2,FALSE),"") -> 764.07659 | E18: 2 | F18: =+IFERROR(D18*E18,"") -> 1528.1532 | K18: =+H18*2.5 -> 0 | L18: =+J18*1.1 -> 0 | M18: =+IF(L18>K18,L18,K18) -> 0 | O18: =+M18-J18 -> 0
B19: Combo familiar | C19: Brownie chocolate | D19: =+IFERROR(VLOOKUP(C19,'3) costo mp'!$B$4:$C$19,2,FALSE),"") -> 578.12713 | E19: 2 | F19: =+IFERROR(D19*E19,"") -> 1156.2543 | K19: =+H19*2.5 -> 0 | L19: =+J19*1.1 -> 0 | M19: =+IF(L19>K19,L19,K19) -> 0 | O19: =+M19-J19 -> 0
B20: Combo familiar | C20: Brownie red velvet | D20: =+IFERROR(VLOOKUP(C20,'3) costo mp'!$B$4:$C$19,2,FALSE),"") -> 539.65357 | E20: 2 | F20: =+IFERROR(D20*E20,"") -> 1079.3071 | K20: =+H20*2.5 -> 0 | L20: =+J20*1.1 -> 0 | M20: =+IF(L20>K20,L20,K20) -> 0 | O20: =+M20-J20 -> 0
B21: Combo mesa dulce | C21: Cookie chip clasica | D21: =+IFERROR(VLOOKUP(C21,'3) costo mp'!$B$4:$C$19,2,FALSE),"") -> 148.49956 | E21: 2 | F21: =+IFERROR(D21*E21,"") -> 296.99912 | G21: =+IFERROR(VLOOKUP(B21,Packaging,6,FALSE),"") -> 216.05734 | H21: =+IFERROR(SUM(F21:F25)+G21,"") -> 3942.5838 | J21: 10000 | K21: =+H21*2.5 -> 9856.4595 | L21: =+J21*1.1 -> 11000 | M21: =+IF(L21>K21,L21,K21) -> 11000 | N21: =+J21-H21 -> 6057.4162 | O21: =+M21-J21 -> 1000 | P21: =(N21/J21) -> 0.60574162
B22: Combo mesa dulce | C22: Cookie red velvet clasica | D22: =+IFERROR(VLOOKUP(C22,'3) costo mp'!$B$4:$C$19,2,FALSE),"") -> 178.04895 | E22: 2 | F22: =+IFERROR(D22*E22,"") -> 356.0979 | K22: =+H22*2.5 -> 0 | L22: =+J22*1.1 -> 0 | M22: =+IF(L22>K22,L22,K22) -> 0 | O22: =+M22-J22 -> 0
B23: Combo mesa dulce | C23: Cookie oreo clasica | D23: =+IFERROR(VLOOKUP(C23,'3) costo mp'!$B$4:$C$19,2,FALSE),"") -> 194.51099 | E23: 2 | F23: =+IFERROR(D23*E23,"") -> 389.02198 | K23: =+H23*2.5 -> 0 | L23: =+J23*1.1 -> 0 | M23: =+IF(L23>K23,L23,K23) -> 0 | O23: =+M23-J23 -> 0
B24: Combo mesa dulce | C24: Brownie chocolate | D24: =+IFERROR(VLOOKUP(C24,'3) costo mp'!$B$4:$C$19,2,FALSE),"") -> 578.12713 | E24: 2 | F24: =+IFERROR(D24*E24,"") -> 1156.2543 | K24: =+H24*2.5 -> 0 | L24: =+J24*1.1 -> 0 | M24: =+IF(L24>K24,L24,K24) -> 0 | O24: =+M24-J24 -> 0
B25: Combo mesa dulce | C25: Brownie oreo | D25: =+IFERROR(VLOOKUP(C25,'3) costo mp'!$B$4:$C$19,2,FALSE),"") -> 764.07659 | E25: 2 | F25: =+IFERROR(D25*E25,"") -> 1528.1532 | K25: =+H25*2.5 -> 0 | L25: =+J25*1.1 -> 0 | M25: =+IF(L25>K25,L25,K25) -> 0 | O25: =+M25-J25 -> 0
B26: Combo rellenas x3 | C26: Cookie vainilla bon o bon | D26: =+IFERROR(VLOOKUP(C26,'3) costo mp'!$B$4:$C$19,2,FALSE),"") -> 1349.762 | E26: 1 | F26: =+IFERROR(D26*E26,"") -> 1349.762 | G26: =+IFERROR(VLOOKUP(B26,Packaging,6,FALSE),"") -> 216.05734 | H26: =+IFERROR(SUM(F26:F28)+G26,"") -> 3554.4322 | J26: 10000 | K26: =+H26*2.5 -> 8886.0806 | L26: =+J26*1.1 -> 11000 | M26: =+IF(L26>K26,L26,K26) -> 11000 | N26: =+J26-H26 -> 6445.5678 | O26: =+M26-J26 -> 1000 | P26: =(N26/J26) -> 0.64455678
B27: Combo rellenas x3 | C27: Cookie limon rellena | D27: =+IFERROR(VLOOKUP(C27,'3) costo mp'!$B$4:$C$19,2,FALSE),"") -> 561.37585 | E27: 1 | F27: =+IFERROR(D27*E27,"") -> 561.37585 | K27: =+H27*2.5 -> 0 | L27: =+J27*1.1 -> 0 | M27: =+IF(L27>K27,L27,K27) -> 0 | O27: =+M27-J27 -> 0
B28: Combo rellenas x3 | C28: Cookie vainilla kinder | D28: =+IFERROR(VLOOKUP(C28,'3) costo mp'!$B$4:$C$19,2,FALSE),"") -> 1427.237 | E28: 1 | F28: =+IFERROR(D28*E28,"") -> 1427.237 | K28: =+H28*2.5 -> 0 | L28: =+J28*1.1 -> 0 | M28: =+IF(L28>K28,L28,K28) -> 0 | O28: =+M28-J28 -> 0
B29: Cookie clasica x1 | C29: Cookie oreo clasica | D29: =+IFERROR(VLOOKUP(C29,'3) costo mp'!$B$4:$C$19,2,FALSE),"") -> 194.51099 | E29: 1 | F29: =+IFERROR(D29*E29,"") -> 194.51099 | G29: =+IFERROR(VLOOKUP(B29,Packaging,6,FALSE),"") -> 149.37234 | H29: =+IFERROR(SUM(F29)+G29,"") -> 343.88333 | J29: 800 | K29: =+H29*2.5 -> 859.70833 | L29: =+J29*1.1 -> 880 | M29: =+IF(L29>K29,L29,K29) -> 880 | N29: =+J29-H29 -> 456.11667 | O29: =+M29-J29 -> 80 | P29: =(N29/J29) -> 0.57014583
B30: Cookie rellena x1 | C30: Cookie Chocotorta | D30: =+IFERROR(VLOOKUP(C30,'3) costo mp'!$B$4:$C$19,2,FALSE),"") -> 589.23391 | E30: 1 | F30: =+IFERROR(D30*E30,"") -> 589.23391 | G30: =+IFERROR(VLOOKUP(B30,Packaging,6,FALSE),"") -> 149.37234 | H30: =+IFERROR(SUM(F30)+G30,"") -> 738.60625 | J30: 3500 | K30: =+H30*2.5 -> 1846.5156 | L30: =+J30*1.1 -> 3850 | M30: =+IF(L30>K30,L30,K30) -> 3850 | N30: =+J30-H30 -> 2761.3937 | O30: =+M30-J30 -> 350 | P30: =(N30/J30) -> 0.78896964
B31: Cookie rellena x1 | C31: Cookie vainilla bon o bon | D31: =+IFERROR(VLOOKUP(C31,'3) costo mp'!$B$4:$C$19,2,FALSE),"") -> 1349.762 | E31: 1 | F31: =+IFERROR(D31*E31,"") -> 1349.762 | G31: =+IFERROR(VLOOKUP(B31,Packaging,6,FALSE),"") -> 149.37234 | H31: =+IFERROR(SUM(F31)+G31,"") -> 1499.1344 | J31: 3500 | K31: =+H31*2.5 -> 3747.8359 | L31: =+J31*1.1 -> 3850 | M31: =+IF(L31>K31,L31,K31) -> 3850 | N31: =+J31-H31 -> 2000.8656 | O31: =+M31-J31 -> 350 | P31: =(N31/J31) -> 0.57167589
B32: Cookie rellena x1 | C32: Cookie vainilla kinder | D32: =+IFERROR(VLOOKUP(C32,'3) costo mp'!$B$4:$C$19,2,FALSE),"") -> 1427.237 | E32: 1 | F32: =+IFERROR(D32*E32,"") -> 1427.237 | G32: =+IFERROR(VLOOKUP(B32,Packaging,6,FALSE),"") -> 149.37234 | H32: =+IFERROR(SUM(F32)+G32,"") -> 1576.6094 | J32: 3500 | K32: =+H32*2.5 -> 3941.5234 | L32: =+J32*1.1 -> 3850 | M32: =+IF(L32>K32,L32,K32) -> 3941.5234 | N32: =+J32-H32 -> 1923.3906 | O32: =+M32-J32 -> 441.52343 | P32: =(N32/J32) -> 0.54954018
B33: Cookie rellena x1 | C33: Cookie red velvet rellena | D33: =+IFERROR(VLOOKUP(C33,'3) costo mp'!$B$4:$C$19,2,FALSE),"") -> 630.08327 | E33: 1 | F33: =+IFERROR(D33*E33,"") -> 630.08327 | G33: =+IFERROR(VLOOKUP(B33,Packaging,6,FALSE),"") -> 149.37234 | H33: =+IFERROR(SUM(F33)+G33,"") -> 779.45561 | J33: 3500 | K33: =+H33*2.5 -> 1948.639 | L33: =+J33*1.1 -> 3850 | M33: =+IF(L33>K33,L33,K33) -> 3850 | N33: =+J33-H33 -> 2720.5444 | O33: =+M33-J33 -> 350 | P33: =(N33/J33) -> 0.7772984
B34: Cookie rellena x1 | C34: Cookie Franui rellena | D34: =+IFERROR(VLOOKUP(C34,'3) costo mp'!$B$4:$C$19,2,FALSE),"") -> 905.60151 | E34: 1 | F34: =+IFERROR(D34*E34,"") -> 905.60151 | G34: =+IFERROR(VLOOKUP(B34,Packaging,6,FALSE),"") -> 149.37234 | H34: =+IFERROR(SUM(F34)+G34,"") -> 1054.9738 | J34: 3500 | K34: =+H34*2.5 -> 2637.4346 | L34: =+J34*1.1 -> 3850 | M34: =+IF(L34>K34,L34,K34) -> 3850 | N34: =+J34-H34 -> 2445.0262 | O34: =+M34-J34 -> 350 | P34: =(N34/J34) -> 0.6985789
B35: Cookie rellena x1 | C35: Cookie limon rellena | D35: =+IFERROR(VLOOKUP(C35,'3) costo mp'!$B$4:$C$19,2,FALSE),"") -> 561.37585 | E35: 1 | F35: =+IFERROR(D35*E35,"") -> 561.37585 | G35: =+IFERROR(VLOOKUP(B35,Packaging,6,FALSE),"") -> 149.37234 | H35: =+IFERROR(SUM(F35)+G35,"") -> 710.74819 | J35: 3500 | K35: =+H35*2.5 -> 1776.8705 | L35: =+J35*1.1 -> 3850 | M35: =+IF(L35>K35,L35,K35) -> 3850 | N35: =+J35-H35 -> 2789.2518 | O35: =+M35-J35 -> 350 | P35: =(N35/J35) -> 0.79692909
B36: Combo rellenas y clasicas | C36: Cookie vainilla kinder | D36: =+IFERROR(VLOOKUP(C36,'3) costo mp'!$B$4:$C$19,2,FALSE),"") -> 1427.237 | E36: 1 | F36: =+IFERROR(D36*E36,"") -> 1427.237 | G36: =+IFERROR(VLOOKUP(B36,Packaging,6,FALSE),"") -> 432.11468 | H36: =+IFERROR(SUM(F36:F42)+G36,"") -> 6122.1817
B37: Combo rellenas y clasicas | C37: Cookie vainilla bon o bon | D37: =+IFERROR(VLOOKUP(C37,'3) costo mp'!$B$4:$C$19,2,FALSE),"") -> 1349.762 | E37: 1 | F37: =+IFERROR(D37*E37,"") -> 1349.762
B38: Combo rellenas y clasicas | C38: Cookie Franui rellena | D38: =+IFERROR(VLOOKUP(C38,'3) costo mp'!$B$4:$C$19,2,FALSE),"") -> 905.60151 | E38: 1 | F38: =+IFERROR(D38*E38,"") -> 905.60151
B39: Combo rellenas y clasicas | C39: Cookie chip clasica | D39: =+IFERROR(VLOOKUP(C39,'3) costo mp'!$B$4:$C$19,2,FALSE),"") -> 148.49956 | E39: 5 | F39: =+IFERROR(D39*E39,"") -> 742.49779
B40: Combo rellenas y clasicas | C40: Cookie limon clasica | D40: =+IFERROR(VLOOKUP(C40,'3) costo mp'!$B$4:$C$19,2,FALSE),"") -> 147.28883 | E40: 1 | F40: =+IFERROR(D40*E40,"") -> 147.28883
B41: Combo rellenas y clasicas | C41: Cookie oreo clasica | D41: =+IFERROR(VLOOKUP(C41,'3) costo mp'!$B$4:$C$19,2,FALSE),"") -> 194.51099 | E41: 3 | F41: =+IFERROR(D41*E41,"") -> 583.53298
...

Sheet Tdinamica
A3: Etiquetas de fila | B3: Suma de Costo x producto | C3: Suma de Costo packaging | D3: Suma de Costo total | E3: COSTO TOTAL | F3: CARTA ACTUAL | G3: MARGEN | H3: PRECIO SUGERIDO
A4: brownie x1 | B4: 578.12713 | C4: 149.37234 | D4: 727.49947 | E4: 727.49947 | F4: 2000 | G4: =+IFERROR((F4-E4)/F4,"") -> 0.63625026 | I4: =+E4*(1+75%) -> 1273.1241
A5: Brownie chocolate | B5: 578.12713 | C5: 149.37234 | D5: 727.49947 | G5: =+IFERROR((F5-E5)/F5,"")
A6: Combo brownies x6 | B6: 3577.7651 | C6: 216.05734 | D6: 3793.8225 | E6: 3793.8225 | F6: 9450 | G6: =+IFERROR((F6-E6)/F6,"") -> 0.5985373
A7: Brownie chocolate | B7: 1734.3814 | G7: =+IFERROR((F7-E7)/F7,"")
A8: Brownie oreo | B8: 764.07659 | G8: =+IFERROR((F8-E8)/F8,"")
A9: Brownie red velvet | B9: 1079.3071 | C9: 216.05734 | D9: 3793.8225 | G9: =+IFERROR((F9-E9)/F9,"")
A10: Combo clasicas x12 | B10: 2007.4664 | C10: 216.05734 | D10: 2223.5238 | E10: 2223.5238 | F10: 8500 | G10: =+IFERROR((F10-E10)/F10,"") -> 0.73840897
A11: Cookie chip clasica | B11: 742.49779 | C11: 216.05734 | D11: 2223.5238 | G11: =+IFERROR((F11-E11)/F11,"")
A12: Cookie limon clasica | B12: 147.28883 | G12: =+IFERROR((F12-E12)/F12,"")
A13: Cookie oreo clasica | B13: 583.53298 | G13: =+IFERROR((F13-E13)/F13,"")
A14: Cookie red velvet clasica | B14: 534.14685 | G14: =+IFERROR((F14-E14)/F14,"")
A15: Combo clasicas x6 | B15: 1042.119 | C15: 149.37234 | D15: 1191.4913 | E15: 1191.4913 | F15: 4500 | G15: =+IFERROR((F15-E15)/F15,"") -> 0.73522415
A16: Cookie chip clasica | B16: 296.99912 | C16: 149.37234 | D16: 1191.4913 | G16: =+IFERROR((F16-E16)/F16,"")
A17: Cookie oreo clasica | B17: 389.02198 | G17: =+IFERROR((F17-E17)/F17,"")
A18: Cookie red velvet clasica | B18: 356.0979 | G18: =+IFERROR((F18-E18)/F18,"")
A19: Combo entre dos | B19: 2691.3853 | C19: 216.05734 | D19: 2907.4426 | E19: 2907.4426 | F19: 8500 | G19: =+IFERROR((F19-E19)/F19,"") -> 0.65794793
A20: Brownie chocolate | B20: 578.12713 | D20: 578.12713 | G20: =+IFERROR((F20-E20)/F20,"")
A21: Cookie chip clasica | B21: 296.99912 | D21: 296.99912 | G21: =+IFERROR((F21-E21)/F21,"")
A22: Cookie oreo clasica | B22: 389.02198 | D22: 389.02198 | G22: =+IFERROR((F22-E22)/F22,"")
A23: Cookie vainilla kinder | B23: 1427.237 | C23: 216.05734 | D23: 1643.2944 | G23: =+IFERROR((F23-E23)/F23,"")
A24: Combo familiar | B24: 5768.7596 | C24: 432.11468 | D24: 6200.8743 | E24: 6200.8743 | F24: 18000 | G24: =+IFERROR((F24-E24)/F24,"") -> 0.65550699
A25: Brownie chocolate | B25: 1156.2543 | G25: =+IFERROR((F25-E25)/F25,"")
A26: Brownie oreo | B26: 1528.1532 | G26: =+IFERROR((F26-E26)/F26,"")
A27: Brownie red velvet | B27: 1079.3071 | G27: =+IFERROR((F27-E27)/F27,"")
A28: Cookie chip clasica | B28: 445.49868 | G28: =+IFERROR((F28-E28)/F28,"")
A29: Cookie limon clasica | B29: 441.86649 | C29: 432.11468 | D29: 6200.8743 | E29: 6200.8743 | G29: =+IFERROR((F29-E29)/F29,"")
A30: Cookie oreo clasica | B30: 583.53298 | G30: =+IFERROR((F30-E30)/F30,"")
A31: Cookie red velvet clasica | B31: 534.14685 | G31: =+IFERROR((F31-E31)/F31,"")
A32: Combo mesa dulce | B32: 3726.5265 | C32: 216.05734 | D32: 3942.5838 | E32: 3942.5838 | F32: 11000 | G32: =+IFERROR((F32-E32)/F32,"") -> 0.64158329
A33: Brownie chocolate | B33: 1156.2543 | G33: =+IFERROR((F33-E33)/F33,"")
A34: Brownie oreo | B34: 1528.1532 | G34: =+IFERROR((F34-E34)/F34,"")
A35: Cookie chip clasica | B35: 296.99912 | C35: 216.05734 | D35: 3942.5838 | E35: 3942.5838 | G35: =+IFERROR((F35-E35)/F35,"")
A36: Cookie oreo clasica | B36: 389.02198 | G36: =+IFERROR((F36-E36)/F36,"")
A37: Cookie red velvet clasica | B37: 356.0979 | G37: =+IFERROR((F37-E37)/F37,"")
A38: Combo para alegrar | B38: 2580.3356 | C38: 216.05734 | D38: 2796.3929 | E38: 2796.3929 | F38: 7000 | G38: =+IFERROR((F38-E38)/F38,"") -> 0.60051529
A39: Brownie oreo | B39: 764.07659 | G39: =+IFERROR((F39-E39)/F39,"")
A40: Cookie oreo clasica | B40: 389.02198 | G40: =+IFERROR((F40-E40)/F40,"")
A41: Cookie vainilla kinder | B41: 1427.237 | C41: 216.05734 | D41: 2796.3929 | G41: =+IFERROR((F41-E41)/F41,"")
A42: Combo para enamorar | B42: 5350.1377 | C42: 432.11468 | D42: 5782.2524 | E42: 5782.2524 | F42: 17000 | G42: =+IFERROR((F42-E42)/F42,"") -> 0.65986751
...

Sheet finales
B3: Producto | C3: Suma de Costo x producto | D3: Suma de Costo packaging | E3: Costo total | F3: Precio actual | G3: Margen actual | H3: Margen 70%
B4: brownie x1 | C4: 578.12713 | D4: 149.37234 | E4: 727.49947 | F4: 2000 | G4: =+(F4-E4)/F4 -> 0.63625026 | H4: =+E4/(1-0.7) -> 2424.9982
B5: Combo brownies x6 | C5: 3577.7651 | D5: 216.05734 | E5: 3793.8225 | F5: 10500 | G5: =+(F5-E5)/F5 -> 0.63868357 | H5: =+E5/(1-0.7) -> 12646.075
B6: Combo brownies x4 | C6: 2460 | D6: 216 | E6: =+D6+C6 -> 2676 | F6: 7500 | G6: =+(F6-E6)/F6 -> 0.6432 | H6: =+E6/(1-0.7) -> 8920
B7: Combo clasicas x12 | C7: 2007.4664 | D7: 216.05734 | E7: 2223.5238 | F7: 8500 | G7: =+(F7-E7)/F7 -> 0.73840897 | H7: =+E7/(1-0.7) -> 7411.746
B8: Combo clasicas x6 | C8: 1042.119 | D8: 149.37234 | E8: 1191.4913 | F8: 4500 | G8: =+(F8-E8)/F8 -> 0.73522415 | H8: =+E8/(1-0.7) -> 3971.6378
B9: Combo entre dos | C9: 2691.3853 | D9: 216.05734 | E9: 2907.4426 | F9: 8500 | G9: =+(F9-E9)/F9 -> 0.65794793 | H9: =+E9/(1-0.7) -> 9691.4754
B10: Combo familiar | C10: 5768.7596 | D10: 432.11468 | E10: 6200.8743 | F10: 18000 | G10: =+(F10-E10)/F10 -> 0.65550699 | H10: =+E10/(1-0.7) -> 20669.581
B11: Combo mesa dulce | C11: 3726.5265 | D11: 216.05734 | E11: 3942.5838 | F11: 11000 | G11: =+(F11-E11)/F11 -> 0.64158329 | H11: =+E11/(1-0.7) -> 13141.946
B12: Combo para alegrar | C12: 2580.3356 | D12: 216.05734 | E12: 2796.3929 | F12: 7000 | G12: =+(F12-E12)/F12 -> 0.60051529 | H12: =+E12/(1-0.7) -> 9321.3098
B13: Combo para enamorar | C13: 5350.1377 | D13: 432.11468 | E13: 5782.2524 | F13: 17000 | G13: =+(F13-E13)/F13 -> 0.65986751 | H13: =+E13/(1-0.7) -> 19274.175
B14: Combo para sorprender | C14: 3030.7319 | D14: 216.05734 | E14: 3246.7892 | F14: 11500 | G14: =+(F14-E14)/F14 -> 0.7176705 | H14: =+E14/(1-0.7) -> 10822.631
B15: Combo rellenas x6 | C15: =+C16*2 -> 6676.7498 | D15: =+D16*2 -> 432.11468 | E15: =+E16*2 -> 7108.8645 | F15: 22000 | G15: =+(F15-E15)/F15 -> 0.6768698 | H15: =+E15/(1-0.7) -> 23696.215
B16: Combo rellenas x3 | C16: 3338.3749 | D16: 216.05734 | E16: 3554.4322 | F16: 11500 | G16: =+(F16-E16)/F16 -> 0.69091893 | H16: =+E16/(1-0.7) -> 11848.107
B17: Combo rellenas y clasicas | C17: 5690.067 | D17: 432.11468 | E17: 6122.1817 | F17: 19000 | G17: =+(F17-E17)/F17 -> 0.67777991 | H17: =+E17/(1-0.7) -> 20407.272
B18: Cookie clasica x1 | C18: 194.51099 | D18: 149.37234 | E18: 343.88333 | F18: 800 | G18: =+(F18-E18)/F18 -> 0.57014583 | H18: =+E18/(1-0.7) -> 1146.2778
B19: Cookie Franui rellena | C19: 905.60151 | D19: 149.37234 | E19: 1054.9738 | F19: 4000 | G19: =+(F19-E19)/F19 -> 0.73625654 | H19: =+E19/(1-0.7) -> 3516.5795
B20: Cookie limon rellena | C20: 561.37585 | D20: 149.37234 | E20: 710.74819 | F20: 3900 | G20: =+(F20-E20)/F20 -> 0.81775688 | H20: =+E20/(1-0.7) -> 2369.1606
B21: Cookie red velvet rellena | C21: 630.08327 | D21: 149.37234 | E21: 779.45561 | F21: 4000 | G21: =+(F21-E21)/F21 -> 0.8051361 | H21: =+E21/(1-0.7) -> 2598.1854
B22: Cookie vainilla bon o bon | C22: 1349.762 | D22: 149.37234 | E22: 1499.1344 | F22: 4000 | G22: =+(F22-E22)/F22 -> 0.62521641 | H22: =+E22/(1-0.7) -> 4997.1146
B23: Cookie vainilla kinder | C23: 1427.237 | D23: 149.37234 | E23: 1576.6094 | F23: 4300 | G23: =+(F23-E23)/F23 -> 0.63334666 | H23: =+E23/(1-0.7) -> 5255.3646
B24: Cookie Chocotorta | C24: 589.23391 | D24: 149.37234 | E24: 738.60625 | F24: 4000 | G24: =+(F24-E24)/F24 -> 0.81534844 | H24: =+E24/(1-0.7) -> 2462.0208

Sheet Lista de precios final
C2: Descripcion producto | D2: Detalle | E2: Cantidad | F2: Precios carta nueva
C3: Combo mesa dulce | D3: Cookie chip clasica | E3: 2 | F3: 11000
D4: Cookie red velvet clasica | E4: 2
D5: Cookie oreo clasica | E5: 2
D6: Brownie chocolate | E6: 2
D7: Brownie oreo | E7: 2
C8: Combo familiar | D8: Cookie limon clasica | E8: 3 | F8: 17600
D9: Cookie oreo clasica | E9: 3
D10: Cookie red velvet clasica | E10: 3
D11: Cookie chip clasica | E11: 3
D12: Brownie oreo | E12: 2
D13: Brownie chocolate | E13: 2
D14: Brownie red velvet | E14: 2
C15: Combo rellenas x3 | D15: Cookie vainilla ferrero | E15: 1 | F15: 11000
D16: Cookie limon rellena | E16: 1
D17: Cookie vainilla kinder | E17: 1
C18: Combo brownies x6 | D18: Brownie red velvet | E18: 2 | F18: 9350
D19: Brownie oreo | E19: 1
D20: Brownie chocolate | E20: 3
C21: Combo clasicas x12 | D21: Cookie chip clasica | E21: 5 | F21: 9350
D22: Cookie limon clasica | E22: 1
D23: Cookie oreo clasica | E23: 3
D24: Cookie red velvet clasica | E24: 3
C25: Combo clasicas x6 | D25: Cookie chip clasica | E25: 2 | F25: 4950
D26: Cookie red velvet clasica | E26: 2
D27: Cookie oreo clasica | E27: 2
C28: Cookie rellena x1 | D28: Cookie vainilla ferrero | E28: 1 | F28: 4500
C29: Cookie rellena x1 | D29: Cookie vainilla bon o bon | E29: 1 | F29: 3850
C30: Cookie rellena x1 | D30: Cookie vainilla kinder | E30: 1 | F30: 3850
C31: Cookie rellena x1 | D31: Cookie red velvet rellena | E31: 1 | F31: 3850
C32: Cookie rellena x1 | D32: Cookie oreo rellena | E32: 1 | F32: 3850
C33: Cookie rellena x1 | D33: Cookie limon rellena | E33: 1 | F33: 3850
C34: Cookie clasica x1 | D34: Cookie oreo clasica | E34: 1 | F34: 880
C35: brownie x1 | D35: Brownie oreo | E35: 1 | F35: 2232.1841

Sheet Anexo 1
B2: Detalle | C2: Peso | D2: simple | E2: rellenas | G2: Detalle para huevos | H2: crema de leche | I2: chocolate
B3: masa red velvet | C3: 4716 | D3: =+ROUNDDOWN(C3/40,0) -> 117 | E3: =+ROUNDDOWN(C3/120,0) -> 39 | G3: Ganash de choco negro | H3: 0.5 | I3: 0.5
B4: masa limon | C4: 4715 | D4: =+ROUNDDOWN(C4/40,0) -> 117 | E4: =+ROUNDDOWN(C4/120,0) -> 39 | G4: Ganash de choco blanco | H4: 0.37 | I4: 0.63
B5: masa oreo | C5: 5260 | D5: =+ROUNDDOWN(C5/40,0) -> 131 | E5: =+ROUNDDOWN(C5/120,0) -> 43
B6: masa vainilla | C6: 4440 | E6: =+ROUNDDOWN(C6/120,0) -> 37
B7: Froasting queso cream | C7: =150+250+25+12.5 -> 437.5 | E7: =+ROUNDDOWN(C7/20,0) -> 21
B8: Ganash chocolate | C8: 400 | E8: =+ROUNDDOWN(C8/15,0) -> 26
B9: Masa chip | C9: 4816 | D9: =+C9/40 -> 120.4
B10: Reduccion Frutos rojos | C10: 709 | D10: ? | E10: =+ROUNDDOWN(C10/13,0) -> 54
G11: Reduccion frutos rojos
G12: Frutos rojos | H12: =+VLOOKUP(G12,'1) Planilla maestra insumos'!$B$3:$D$98,2,FALSE) -> kg | I12: 2 | J12: =+I12/$I$15 -> 0.75757576
G13: Azucar blanca | H13: =+VLOOKUP(G13,'1) Planilla maestra insumos'!$B$3:$D$98,2,FALSE) -> kg | I13: 0.6 | J13: =+I13/$I$15 -> 0.22727273
G14: Limon (jugo de limon) | H14: =+VLOOKUP(G14,'1) Planilla maestra insumos'!$B$3:$D$98,2,FALSE) -> kg | I14: 0.04 | J14: =+I14/$I$15 -> 0.015151515
I15: =SUM(I12:I14) -> 2.64
G19: Crema de chantilly
G20: crema de leche | H20: gr | I20: 100 | J20: =+I20/$I$22 -> 0.83333333
G21: azucar impalpable | H21: gr | I21: 20 | J21: =+I21/$I$22 -> 0.16666667
I22: =SUM(I20:I21) -> 120
